[Tue Apr 19 12:17:26.622975 2016] [:error] [pid 29988] [client 66.249.78.202:53460] mod_wsgi (pid=29988): Target WSGI script '/home/muslu/django/djangohata/djangohata/wsgi.py' cannot be loaded as Python module.
[Tue Apr 19 12:17:26.623061 2016] [:error] [pid 29988] [client 66.249.78.202:53460] mod_wsgi (pid=29988): Exception occurred processing WSGI script '/home/muslu/django/djangohata/djangohata/wsgi.py'.
[Tue Apr 19 12:17:26.623118 2016] [:error] [pid 29988] [client 66.249.78.202:53460] Traceback (most recent call last):
[Tue Apr 19 12:17:26.623167 2016] [:error] [pid 29988] [client 66.249.78.202:53460]   File "/home/muslu/django/djangohata/djangohata/wsgi.py", line 12, in <module>
[Tue Apr 19 12:17:26.623317 2016] [:error] [pid 29988] [client 66.249.78.202:53460]     application = get_wsgi_application()
[Tue Apr 19 12:17:26.623346 2016] [:error] [pid 29988] [client 66.249.78.202:53460]   File "/usr/local/lib/python2.7/dist-packages/django/core/wsgi.py", line 14, in get_wsgi_application
[Tue Apr 19 12:17:26.623442 2016] [:error] [pid 29988] [client 66.249.78.202:53460]     django.setup()
[Tue Apr 19 12:17:26.623469 2016] [:error] [pid 29988] [client 66.249.78.202:53460]   File "/usr/local/lib/python2.7/dist-packages/django/__init__.py", line 18, in setup
[Tue Apr 19 12:17:26.623562 2016] [:error] [pid 29988] [client 66.249.78.202:53460]     apps.populate(settings.INSTALLED_APPS)
[Tue Apr 19 12:17:26.623591 2016] [:error] [pid 29988] [client 66.249.78.202:53460]   File "/usr/local/lib/python2.7/dist-packages/django/apps/registry.py", line 115, in populate
[Tue Apr 19 12:17:26.623955 2016] [:error] [pid 29988] [client 66.249.78.202:53460]     app_config.ready()
[Tue Apr 19 12:17:26.623983 2016] [:error] [pid 29988] [client 66.249.78.202:53460]   File "/usr/local/lib/python2.7/dist-packages/debug_toolbar/apps.py", line 15, in ready
[Tue Apr 19 12:17:26.628732 2016] [:error] [pid 29988] [client 66.249.78.202:53460]     dt_settings.patch_all()
[Tue Apr 19 12:17:26.628768 2016] [:error] [pid 29988] [client 66.249.78.202:53460]   File "/usr/local/lib/python2.7/dist-packages/debug_toolbar/settings.py", line 228, in patch_all
[Tue Apr 19 12:17:26.632801 2016] [:error] [pid 29988] [client 66.249.78.202:53460]     patch_root_urlconf()
[Tue Apr 19 12:17:26.632844 2016] [:error] [pid 29988] [client 66.249.78.202:53460]   File "/usr/local/lib/python2.7/dist-packages/debug_toolbar/settings.py", line 216, in patch_root_urlconf
[Tue Apr 19 12:17:26.632896 2016] [:error] [pid 29988] [client 66.249.78.202:53460]     reverse('djdt:render_panel')
[Tue Apr 19 12:17:26.632922 2016] [:error] [pid 29988] [client 66.249.78.202:53460]   File "/usr/local/lib/python2.7/dist-packages/django/core/urlresolvers.py", line 549, in reverse
[Tue Apr 19 12:17:26.633417 2016] [:error] [pid 29988] [client 66.249.78.202:53460]     app_list = resolver.app_dict[ns]
[Tue Apr 19 12:17:26.633446 2016] [:error] [pid 29988] [client 66.249.78.202:53460]   File "/usr/local/lib/python2.7/dist-packages/django/core/urlresolvers.py", line 351, in app_dict
[Tue Apr 19 12:17:26.633488 2016] [:error] [pid 29988] [client 66.249.78.202:53460]     self._populate()
[Tue Apr 19 12:17:26.633516 2016] [:error] [pid 29988] [client 66.249.78.202:53460]   File "/usr/local/lib/python2.7/dist-packages/django/core/urlresolvers.py", line 284, in _populate
[Tue Apr 19 12:17:26.633557 2016] [:error] [pid 29988] [client 66.249.78.202:53460]     for pattern in reversed(self.url_patterns):
[Tue Apr 19 12:17:26.633583 2016] [:error] [pid 29988] [client 66.249.78.202:53460]   File "/usr/local/lib/python2.7/dist-packages/django/core/urlresolvers.py", line 401, in url_patterns
[Tue Apr 19 12:17:26.633624 2016] [:error] [pid 29988] [client 66.249.78.202:53460]     patterns = getattr(self.urlconf_module, "urlpatterns", self.urlconf_module)
[Tue Apr 19 12:17:26.633649 2016] [:error] [pid 29988] [client 66.249.78.202:53460]   File "/usr/local/lib/python2.7/dist-packages/django/core/urlresolvers.py", line 395, in urlconf_module
[Tue Apr 19 12:17:26.633687 2016] [:error] [pid 29988] [client 66.249.78.202:53460]     self._urlconf_module = import_module(self.urlconf_name)
[Tue Apr 19 12:17:26.633732 2016] [:error] [pid 29988] [client 66.249.78.202:53460]   File "/usr/lib/python2.7/importlib/__init__.py", line 37, in import_module
[Tue Apr 19 12:17:26.633839 2016] [:error] [pid 29988] [client 66.249.78.202:53460]     __import__(name)
[Tue Apr 19 12:17:26.633867 2016] [:error] [pid 29988] [client 66.249.78.202:53460]   File "/home/muslu/django/djangohata/djangohata/urls.py", line 5, in <module>
[Tue Apr 19 12:17:26.633979 2016] [:error] [pid 29988] [client 66.249.78.202:53460]     from hatalar.views import anasayfa, hatabul, detaygoster
[Tue Apr 19 12:17:26.634007 2016] [:error] [pid 29988] [client 66.249.78.202:53460]   File "/home/muslu/django/djangohata/hatalar/views.py", line 17, in <module>
[Tue Apr 19 12:17:26.634163 2016] [:error] [pid 29988] [client 66.249.78.202:53460]     conn = MySQLdb.connect(host="localhost", user="root", passwd="", db="HataBull", charset="utf8", use_unicode=True)
[Tue Apr 19 12:17:26.634195 2016] [:error] [pid 29988] [client 66.249.78.202:53460]   File "/usr/lib/python2.7/dist-packages/MySQLdb/__init__.py", line 81, in Connect
[Tue Apr 19 12:17:26.638804 2016] [:error] [pid 29988] [client 66.249.78.202:53460]     return Connection(*args, **kwargs)
[Tue Apr 19 12:17:26.638836 2016] [:error] [pid 29988] [client 66.249.78.202:53460]   File "/usr/lib/python2.7/dist-packages/MySQLdb/connections.py", line 187, in __init__
[Tue Apr 19 12:17:26.642946 2016] [:error] [pid 29988] [client 66.249.78.202:53460]     super(Connection, self).__init__(*args, **kwargs2)
[Tue Apr 19 12:17:26.643072 2016] [:error] [pid 29988] [client 66.249.78.202:53460] OperationalError: (1045, "Access denied for user 'root'@'localhost' (using password: NO)")
[Tue Apr 19 12:17:29.641299 2016] [:error] [pid 30022] [client 193.140.109.2:16652] mod_wsgi (pid=30022): Target WSGI script '/home/muslu/django/djangohata/djangohata/wsgi.py' cannot be loaded as Python module., referer: https://www.facebook.com/
[Tue Apr 19 12:17:29.641360 2016] [:error] [pid 30022] [client 193.140.109.2:16652] mod_wsgi (pid=30022): Exception occurred processing WSGI script '/home/muslu/django/djangohata/djangohata/wsgi.py'., referer: https://www.facebook.com/
[Tue Apr 19 12:17:29.641415 2016] [:error] [pid 30022] [client 193.140.109.2:16652] Traceback (most recent call last):, referer: https://www.facebook.com/
[Tue Apr 19 12:17:29.641465 2016] [:error] [pid 30022] [client 193.140.109.2:16652]   File "/home/muslu/django/djangohata/djangohata/wsgi.py", line 12, in <module>, referer: https://www.facebook.com/
[Tue Apr 19 12:17:29.641600 2016] [:error] [pid 30022] [client 193.140.109.2:16652]     application = get_wsgi_application(), referer: https://www.facebook.com/
[Tue Apr 19 12:17:29.641630 2016] [:error] [pid 30022] [client 193.140.109.2:16652]   File "/usr/local/lib/python2.7/dist-packages/django/core/wsgi.py", line 14, in get_wsgi_application, referer: https://www.facebook.com/
[Tue Apr 19 12:17:29.641728 2016] [:error] [pid 30022] [client 193.140.109.2:16652]     django.setup(), referer: https://www.facebook.com/
[Tue Apr 19 12:17:29.641757 2016] [:error] [pid 30022] [client 193.140.109.2:16652]   File "/usr/local/lib/python2.7/dist-packages/django/__init__.py", line 18, in setup, referer: https://www.facebook.com/
[Tue Apr 19 12:17:29.641852 2016] [:error] [pid 30022] [client 193.140.109.2:16652]     apps.populate(settings.INSTALLED_APPS), referer: https://www.facebook.com/
[Tue Apr 19 12:17:29.641880 2016] [:error] [pid 30022] [client 193.140.109.2:16652]   File "/usr/local/lib/python2.7/dist-packages/django/apps/registry.py", line 115, in populate, referer: https://www.facebook.com/
[Tue Apr 19 12:17:29.642275 2016] [:error] [pid 30022] [client 193.140.109.2:16652]     app_config.ready(), referer: https://www.facebook.com/
[Tue Apr 19 12:17:29.642304 2016] [:error] [pid 30022] [client 193.140.109.2:16652]   File "/usr/local/lib/python2.7/dist-packages/debug_toolbar/apps.py", line 15, in ready, referer: https://www.facebook.com/
[Tue Apr 19 12:17:29.642590 2016] [:error] [pid 30022] [client 193.140.109.2:16652]     dt_settings.patch_all(), referer: https://www.facebook.com/
[Tue Apr 19 12:17:29.642639 2016] [:error] [pid 30022] [client 193.140.109.2:16652]   File "/usr/local/lib/python2.7/dist-packages/debug_toolbar/settings.py", line 228, in patch_all, referer: https://www.facebook.com/
[Tue Apr 19 12:17:29.642823 2016] [:error] [pid 30022] [client 193.140.109.2:16652]     patch_root_urlconf(), referer: https://www.facebook.com/
[Tue Apr 19 12:17:29.642852 2016] [:error] [pid 30022] [client 193.140.109.2:16652]   File "/usr/local/lib/python2.7/dist-packages/debug_toolbar/settings.py", line 216, in patch_root_urlconf, referer: https://www.facebook.com/
[Tue Apr 19 12:17:29.642894 2016] [:error] [pid 30022] [client 193.140.109.2:16652]     reverse('djdt:render_panel'), referer: https://www.facebook.com/
[Tue Apr 19 12:17:29.642919 2016] [:error] [pid 30022] [client 193.140.109.2:16652]   File "/usr/local/lib/python2.7/dist-packages/django/core/urlresolvers.py", line 549, in reverse, referer: https://www.facebook.com/
[Tue Apr 19 12:17:29.643409 2016] [:error] [pid 30022] [client 193.140.109.2:16652]     app_list = resolver.app_dict[ns], referer: https://www.facebook.com/
[Tue Apr 19 12:17:29.643441 2016] [:error] [pid 30022] [client 193.140.109.2:16652]   File "/usr/local/lib/python2.7/dist-packages/django/core/urlresolvers.py", line 351, in app_dict, referer: https://www.facebook.com/
[Tue Apr 19 12:17:29.643486 2016] [:error] [pid 30022] [client 193.140.109.2:16652]     self._populate(), referer: https://www.facebook.com/
[Tue Apr 19 12:17:29.643509 2016] [:error] [pid 30022] [client 193.140.109.2:16652]   File "/usr/local/lib/python2.7/dist-packages/django/core/urlresolvers.py", line 284, in _populate, referer: https://www.facebook.com/
[Tue Apr 19 12:17:29.643534 2016] [:error] [pid 30022] [client 193.140.109.2:16652]     for pattern in reversed(self.url_patterns):, referer: https://www.facebook.com/
[Tue Apr 19 12:17:29.643559 2016] [:error] [pid 30022] [client 193.140.109.2:16652]   File "/usr/local/lib/python2.7/dist-packages/django/core/urlresolvers.py", line 401, in url_patterns, referer: https://www.facebook.com/
[Tue Apr 19 12:17:29.643600 2016] [:error] [pid 30022] [client 193.140.109.2:16652]     patterns = getattr(self.urlconf_module, "urlpatterns", self.urlconf_module), referer: https://www.facebook.com/
[Tue Apr 19 12:17:29.643626 2016] [:error] [pid 30022] [client 193.140.109.2:16652]   File "/usr/local/lib/python2.7/dist-packages/django/core/urlresolvers.py", line 395, in urlconf_module, referer: https://www.facebook.com/
[Tue Apr 19 12:17:29.643666 2016] [:error] [pid 30022] [client 193.140.109.2:16652]     self._urlconf_module = import_module(self.urlconf_name), referer: https://www.facebook.com/
[Tue Apr 19 12:17:29.643691 2016] [:error] [pid 30022] [client 193.140.109.2:16652]   File "/usr/lib/python2.7/importlib/__init__.py", line 37, in import_module, referer: https://www.facebook.com/
[Tue Apr 19 12:17:29.643788 2016] [:error] [pid 30022] [client 193.140.109.2:16652]     __import__(name), referer: https://www.facebook.com/
[Tue Apr 19 12:17:29.643812 2016] [:error] [pid 30022] [client 193.140.109.2:16652]   File "/home/muslu/django/djangohata/djangohata/urls.py", line 5, in <module>, referer: https://www.facebook.com/
[Tue Apr 19 12:17:29.643912 2016] [:error] [pid 30022] [client 193.140.109.2:16652]     from hatalar.views import anasayfa, hatabul, detaygoster, referer: https://www.facebook.com/
[Tue Apr 19 12:17:29.643936 2016] [:error] [pid 30022] [client 193.140.109.2:16652]   File "/home/muslu/django/djangohata/hatalar/views.py", line 17, in <module>, referer: https://www.facebook.com/
[Tue Apr 19 12:17:29.644213 2016] [:error] [pid 30022] [client 193.140.109.2:16652]     conn = MySQLdb.connect(host="localhost", user="root", passwd="", db="HataBull", charset="utf8", use_unicode=True), referer: https://www.facebook.com/
[Tue Apr 19 12:17:29.644243 2016] [:error] [pid 30022] [client 193.140.109.2:16652]   File "/usr/lib/python2.7/dist-packages/MySQLdb/__init__.py", line 81, in Connect, referer: https://www.facebook.com/
[Tue Apr 19 12:17:29.644381 2016] [:error] [pid 30022] [client 193.140.109.2:16652]     return Connection(*args, **kwargs), referer: https://www.facebook.com/
[Tue Apr 19 12:17:29.644409 2016] [:error] [pid 30022] [client 193.140.109.2:16652]   File "/usr/lib/python2.7/dist-packages/MySQLdb/connections.py", line 187, in __init__, referer: https://www.facebook.com/
[Tue Apr 19 12:17:29.644618 2016] [:error] [pid 30022] [client 193.140.109.2:16652]     super(Connection, self).__init__(*args, **kwargs2), referer: https://www.facebook.com/
[Tue Apr 19 12:17:29.644675 2016] [:error] [pid 30022] [client 193.140.109.2:16652] OperationalError: (1045, "Access denied for user 'root'@'localhost' (using password: NO)"), referer: https://www.facebook.com/
[Tue Apr 19 12:18:16.102584 2016] [:error] [pid 29989] [client 78.178.8.189:64675] mod_wsgi (pid=29989): Target WSGI script '/home/muslu/django/djangohata/djangohata/wsgi.py' cannot be loaded as Python module.
[Tue Apr 19 12:18:16.102817 2016] [:error] [pid 29989] [client 78.178.8.189:64675] mod_wsgi (pid=29989): Exception occurred processing WSGI script '/home/muslu/django/djangohata/djangohata/wsgi.py'.
[Tue Apr 19 12:18:16.102921 2016] [:error] [pid 29989] [client 78.178.8.189:64675] Traceback (most recent call last):
[Tue Apr 19 12:18:16.102994 2016] [:error] [pid 29989] [client 78.178.8.189:64675]   File "/home/muslu/django/djangohata/djangohata/wsgi.py", line 12, in <module>
[Tue Apr 19 12:18:16.103196 2016] [:error] [pid 29989] [client 78.178.8.189:64675]     application = get_wsgi_application()
[Tue Apr 19 12:18:16.103229 2016] [:error] [pid 29989] [client 78.178.8.189:64675]   File "/usr/local/lib/python2.7/dist-packages/django/core/wsgi.py", line 14, in get_wsgi_application
[Tue Apr 19 12:18:16.103345 2016] [:error] [pid 29989] [client 78.178.8.189:64675]     django.setup()
[Tue Apr 19 12:18:16.103375 2016] [:error] [pid 29989] [client 78.178.8.189:64675]   File "/usr/local/lib/python2.7/dist-packages/django/__init__.py", line 18, in setup
[Tue Apr 19 12:18:16.103466 2016] [:error] [pid 29989] [client 78.178.8.189:64675]     apps.populate(settings.INSTALLED_APPS)
[Tue Apr 19 12:18:16.103494 2016] [:error] [pid 29989] [client 78.178.8.189:64675]   File "/usr/local/lib/python2.7/dist-packages/django/apps/registry.py", line 115, in populate
[Tue Apr 19 12:18:16.103824 2016] [:error] [pid 29989] [client 78.178.8.189:64675]     app_config.ready()
[Tue Apr 19 12:18:16.103853 2016] [:error] [pid 29989] [client 78.178.8.189:64675]   File "/usr/local/lib/python2.7/dist-packages/debug_toolbar/apps.py", line 15, in ready
[Tue Apr 19 12:18:16.103940 2016] [:error] [pid 29989] [client 78.178.8.189:64675]     dt_settings.patch_all()
[Tue Apr 19 12:18:16.103967 2016] [:error] [pid 29989] [client 78.178.8.189:64675]   File "/usr/local/lib/python2.7/dist-packages/debug_toolbar/settings.py", line 228, in patch_all
[Tue Apr 19 12:18:16.104148 2016] [:error] [pid 29989] [client 78.178.8.189:64675]     patch_root_urlconf()
[Tue Apr 19 12:18:16.104180 2016] [:error] [pid 29989] [client 78.178.8.189:64675]   File "/usr/local/lib/python2.7/dist-packages/debug_toolbar/settings.py", line 216, in patch_root_urlconf
[Tue Apr 19 12:18:16.104223 2016] [:error] [pid 29989] [client 78.178.8.189:64675]     reverse('djdt:render_panel')
[Tue Apr 19 12:18:16.104248 2016] [:error] [pid 29989] [client 78.178.8.189:64675]   File "/usr/local/lib/python2.7/dist-packages/django/core/urlresolvers.py", line 549, in reverse
[Tue Apr 19 12:18:16.104639 2016] [:error] [pid 29989] [client 78.178.8.189:64675]     app_list = resolver.app_dict[ns]
[Tue Apr 19 12:18:16.104666 2016] [:error] [pid 29989] [client 78.178.8.189:64675]   File "/usr/local/lib/python2.7/dist-packages/django/core/urlresolvers.py", line 351, in app_dict
[Tue Apr 19 12:18:16.104701 2016] [:error] [pid 29989] [client 78.178.8.189:64675]     self._populate()
[Tue Apr 19 12:18:16.104725 2016] [:error] [pid 29989] [client 78.178.8.189:64675]   File "/usr/local/lib/python2.7/dist-packages/django/core/urlresolvers.py", line 284, in _populate
[Tue Apr 19 12:18:16.104795 2016] [:error] [pid 29989] [client 78.178.8.189:64675]     for pattern in reversed(self.url_patterns):
[Tue Apr 19 12:18:16.104820 2016] [:error] [pid 29989] [client 78.178.8.189:64675]   File "/usr/local/lib/python2.7/dist-packages/django/core/urlresolvers.py", line 401, in url_patterns
[Tue Apr 19 12:18:16.104858 2016] [:error] [pid 29989] [client 78.178.8.189:64675]     patterns = getattr(self.urlconf_module, "urlpatterns", self.urlconf_module)
[Tue Apr 19 12:18:16.104877 2016] [:error] [pid 29989] [client 78.178.8.189:64675]   File "/usr/local/lib/python2.7/dist-packages/django/core/urlresolvers.py", line 395, in urlconf_module
[Tue Apr 19 12:18:16.104909 2016] [:error] [pid 29989] [client 78.178.8.189:64675]     self._urlconf_module = import_module(self.urlconf_name)
[Tue Apr 19 12:18:16.104933 2016] [:error] [pid 29989] [client 78.178.8.189:64675]   File "/usr/lib/python2.7/importlib/__init__.py", line 37, in import_module
[Tue Apr 19 12:18:16.105025 2016] [:error] [pid 29989] [client 78.178.8.189:64675]     __import__(name)
[Tue Apr 19 12:18:16.105044 2016] [:error] [pid 29989] [client 78.178.8.189:64675]   File "/home/muslu/django/djangohata/djangohata/urls.py", line 5, in <module>
[Tue Apr 19 12:18:16.105187 2016] [:error] [pid 29989] [client 78.178.8.189:64675]     from hatalar.views import anasayfa, hatabul, detaygoster
[Tue Apr 19 12:18:16.105217 2016] [:error] [pid 29989] [client 78.178.8.189:64675]   File "/home/muslu/django/djangohata/hatalar/views.py", line 17, in <module>
[Tue Apr 19 12:18:16.105364 2016] [:error] [pid 29989] [client 78.178.8.189:64675]     conn = MySQLdb.connect(host="localhost", user="root", passwd="", db="HataBull", charset="utf8", use_unicode=True)
[Tue Apr 19 12:18:16.105396 2016] [:error] [pid 29989] [client 78.178.8.189:64675]   File "/usr/lib/python2.7/dist-packages/MySQLdb/__init__.py", line 81, in Connect
[Tue Apr 19 12:18:16.105523 2016] [:error] [pid 29989] [client 78.178.8.189:64675]     return Connection(*args, **kwargs)
[Tue Apr 19 12:18:16.105556 2016] [:error] [pid 29989] [client 78.178.8.189:64675]   File "/usr/lib/python2.7/dist-packages/MySQLdb/connections.py", line 187, in __init__
[Tue Apr 19 12:18:16.105779 2016] [:error] [pid 29989] [client 78.178.8.189:64675]     super(Connection, self).__init__(*args, **kwargs2)
[Tue Apr 19 12:18:16.105861 2016] [:error] [pid 29989] [client 78.178.8.189:64675] OperationalError: (1045, "Access denied for user 'root'@'localhost' (using password: NO)")
[Tue Apr 19 12:18:19.204539 2016] [:error] [pid 30017] [client 78.178.8.189:64676] mod_wsgi (pid=30017): Target WSGI script '/home/muslu/django/djangohata/djangohata/wsgi.py' cannot be loaded as Python module.
[Tue Apr 19 12:18:19.204612 2016] [:error] [pid 30017] [client 78.178.8.189:64676] mod_wsgi (pid=30017): Exception occurred processing WSGI script '/home/muslu/django/djangohata/djangohata/wsgi.py'.
[Tue Apr 19 12:18:19.204661 2016] [:error] [pid 30017] [client 78.178.8.189:64676] Traceback (most recent call last):
[Tue Apr 19 12:18:19.204702 2016] [:error] [pid 30017] [client 78.178.8.189:64676]   File "/home/muslu/django/djangohata/djangohata/wsgi.py", line 12, in <module>
[Tue Apr 19 12:18:19.204841 2016] [:error] [pid 30017] [client 78.178.8.189:64676]     application = get_wsgi_application()
[Tue Apr 19 12:18:19.204870 2016] [:error] [pid 30017] [client 78.178.8.189:64676]   File "/usr/local/lib/python2.7/dist-packages/django/core/wsgi.py", line 14, in get_wsgi_application
[Tue Apr 19 12:18:19.204963 2016] [:error] [pid 30017] [client 78.178.8.189:64676]     django.setup()
[Tue Apr 19 12:18:19.204995 2016] [:error] [pid 30017] [client 78.178.8.189:64676]   File "/usr/local/lib/python2.7/dist-packages/django/__init__.py", line 17, in setup
[Tue Apr 19 12:18:19.205171 2016] [:error] [pid 30017] [client 78.178.8.189:64676]     configure_logging(settings.LOGGING_CONFIG, settings.LOGGING)
[Tue Apr 19 12:18:19.205222 2016] [:error] [pid 30017] [client 78.178.8.189:64676]   File "/usr/local/lib/python2.7/dist-packages/django/conf/__init__.py", line 48, in __getattr__
[Tue Apr 19 12:18:19.205458 2016] [:error] [pid 30017] [client 78.178.8.189:64676]     self._setup(name)
[Tue Apr 19 12:18:19.205487 2016] [:error] [pid 30017] [client 78.178.8.189:64676]   File "/usr/local/lib/python2.7/dist-packages/django/conf/__init__.py", line 44, in _setup
[Tue Apr 19 12:18:19.205533 2016] [:error] [pid 30017] [client 78.178.8.189:64676]     self._wrapped = Settings(settings_module)
[Tue Apr 19 12:18:19.205558 2016] [:error] [pid 30017] [client 78.178.8.189:64676]   File "/usr/local/lib/python2.7/dist-packages/django/conf/__init__.py", line 92, in __init__
[Tue Apr 19 12:18:19.205598 2016] [:error] [pid 30017] [client 78.178.8.189:64676]     mod = importlib.import_module(self.SETTINGS_MODULE)
[Tue Apr 19 12:18:19.205623 2016] [:error] [pid 30017] [client 78.178.8.189:64676]   File "/usr/lib/python2.7/importlib/__init__.py", line 37, in import_module
[Tue Apr 19 12:18:19.205733 2016] [:error] [pid 30017] [client 78.178.8.189:64676]     __import__(name)
[Tue Apr 19 12:18:19.205784 2016] [:error] [pid 30017] [client 78.178.8.189:64676] ImportError: No module named grafsoncom.settings
[Tue Apr 19 12:18:42.124695 2016] [:error] [pid 30018] [client 78.178.8.189:64683] mod_wsgi (pid=30018): Target WSGI script '/home/muslu/django/djangohata/djangohata/wsgi.py' cannot be loaded as Python module., referer: https://www.facebook.com/
[Tue Apr 19 12:18:42.124809 2016] [:error] [pid 30018] [client 78.178.8.189:64683] mod_wsgi (pid=30018): Exception occurred processing WSGI script '/home/muslu/django/djangohata/djangohata/wsgi.py'., referer: https://www.facebook.com/
[Tue Apr 19 12:18:42.124861 2016] [:error] [pid 30018] [client 78.178.8.189:64683] Traceback (most recent call last):, referer: https://www.facebook.com/
[Tue Apr 19 12:18:42.124899 2016] [:error] [pid 30018] [client 78.178.8.189:64683]   File "/home/muslu/django/djangohata/djangohata/wsgi.py", line 12, in <module>, referer: https://www.facebook.com/
[Tue Apr 19 12:18:42.125021 2016] [:error] [pid 30018] [client 78.178.8.189:64683]     application = get_wsgi_application(), referer: https://www.facebook.com/
[Tue Apr 19 12:18:42.125085 2016] [:error] [pid 30018] [client 78.178.8.189:64683]   File "/usr/local/lib/python2.7/dist-packages/django/core/wsgi.py", line 14, in get_wsgi_application, referer: https://www.facebook.com/
[Tue Apr 19 12:18:42.125175 2016] [:error] [pid 30018] [client 78.178.8.189:64683]     django.setup(), referer: https://www.facebook.com/
[Tue Apr 19 12:18:42.125196 2016] [:error] [pid 30018] [client 78.178.8.189:64683]   File "/usr/local/lib/python2.7/dist-packages/django/__init__.py", line 18, in setup, referer: https://www.facebook.com/
[Tue Apr 19 12:18:42.125254 2016] [:error] [pid 30018] [client 78.178.8.189:64683]     apps.populate(settings.INSTALLED_APPS), referer: https://www.facebook.com/
[Tue Apr 19 12:18:42.125273 2016] [:error] [pid 30018] [client 78.178.8.189:64683]   File "/usr/local/lib/python2.7/dist-packages/django/apps/registry.py", line 115, in populate, referer: https://www.facebook.com/
[Tue Apr 19 12:18:42.125535 2016] [:error] [pid 30018] [client 78.178.8.189:64683]     app_config.ready(), referer: https://www.facebook.com/
[Tue Apr 19 12:18:42.125570 2016] [:error] [pid 30018] [client 78.178.8.189:64683]   File "/usr/local/lib/python2.7/dist-packages/debug_toolbar/apps.py", line 15, in ready, referer: https://www.facebook.com/
[Tue Apr 19 12:18:42.125645 2016] [:error] [pid 30018] [client 78.178.8.189:64683]     dt_settings.patch_all(), referer: https://www.facebook.com/
[Tue Apr 19 12:18:42.125665 2016] [:error] [pid 30018] [client 78.178.8.189:64683]   File "/usr/local/lib/python2.7/dist-packages/debug_toolbar/settings.py", line 228, in patch_all, referer: https://www.facebook.com/
[Tue Apr 19 12:18:42.125803 2016] [:error] [pid 30018] [client 78.178.8.189:64683]     patch_root_urlconf(), referer: https://www.facebook.com/
[Tue Apr 19 12:18:42.125832 2016] [:error] [pid 30018] [client 78.178.8.189:64683]   File "/usr/local/lib/python2.7/dist-packages/debug_toolbar/settings.py", line 216, in patch_root_urlconf, referer: https://www.facebook.com/
[Tue Apr 19 12:18:42.125998 2016] [:error] [pid 30018] [client 78.178.8.189:64683]     reverse('djdt:render_panel'), referer: https://www.facebook.com/
[Tue Apr 19 12:18:42.126030 2016] [:error] [pid 30018] [client 78.178.8.189:64683]   File "/usr/local/lib/python2.7/dist-packages/django/core/urlresolvers.py", line 549, in reverse, referer: https://www.facebook.com/
[Tue Apr 19 12:18:42.126438 2016] [:error] [pid 30018] [client 78.178.8.189:64683]     app_list = resolver.app_dict[ns], referer: https://www.facebook.com/
[Tue Apr 19 12:18:42.126470 2016] [:error] [pid 30018] [client 78.178.8.189:64683]   File "/usr/local/lib/python2.7/dist-packages/django/core/urlresolvers.py", line 351, in app_dict, referer: https://www.facebook.com/
[Tue Apr 19 12:18:42.126516 2016] [:error] [pid 30018] [client 78.178.8.189:64683]     self._populate(), referer: https://www.facebook.com/
[Tue Apr 19 12:18:42.126543 2016] [:error] [pid 30018] [client 78.178.8.189:64683]   File "/usr/local/lib/python2.7/dist-packages/django/core/urlresolvers.py", line 284, in _populate, referer: https://www.facebook.com/
[Tue Apr 19 12:18:42.126583 2016] [:error] [pid 30018] [client 78.178.8.189:64683]     for pattern in reversed(self.url_patterns):, referer: https://www.facebook.com/
[Tue Apr 19 12:18:42.126608 2016] [:error] [pid 30018] [client 78.178.8.189:64683]   File "/usr/local/lib/python2.7/dist-packages/django/core/urlresolvers.py", line 401, in url_patterns, referer: https://www.facebook.com/
[Tue Apr 19 12:18:42.126648 2016] [:error] [pid 30018] [client 78.178.8.189:64683]     patterns = getattr(self.urlconf_module, "urlpatterns", self.urlconf_module), referer: https://www.facebook.com/
[Tue Apr 19 12:18:42.126677 2016] [:error] [pid 30018] [client 78.178.8.189:64683]   File "/usr/local/lib/python2.7/dist-packages/django/core/urlresolvers.py", line 395, in urlconf_module, referer: https://www.facebook.com/
[Tue Apr 19 12:18:42.126719 2016] [:error] [pid 30018] [client 78.178.8.189:64683]     self._urlconf_module = import_module(self.urlconf_name), referer: https://www.facebook.com/
[Tue Apr 19 12:18:42.126748 2016] [:error] [pid 30018] [client 78.178.8.189:64683]   File "/usr/lib/python2.7/importlib/__init__.py", line 37, in import_module, referer: https://www.facebook.com/
[Tue Apr 19 12:18:42.126861 2016] [:error] [pid 30018] [client 78.178.8.189:64683]     __import__(name), referer: https://www.facebook.com/
[Tue Apr 19 12:18:42.126889 2016] [:error] [pid 30018] [client 78.178.8.189:64683]   File "/home/muslu/django/djangohata/djangohata/urls.py", line 5, in <module>, referer: https://www.facebook.com/
[Tue Apr 19 12:18:42.127022 2016] [:error] [pid 30018] [client 78.178.8.189:64683]     from hatalar.views import anasayfa, hatabul, detaygoster, referer: https://www.facebook.com/
[Tue Apr 19 12:18:42.127054 2016] [:error] [pid 30018] [client 78.178.8.189:64683]   File "/home/muslu/django/djangohata/hatalar/views.py", line 17, in <module>, referer: https://www.facebook.com/
[Tue Apr 19 12:18:42.127234 2016] [:error] [pid 30018] [client 78.178.8.189:64683]     conn = MySQLdb.connect(host="localhost", user="root", passwd="", db="HataBull", charset="utf8", use_unicode=True), referer: https://www.facebook.com/
[Tue Apr 19 12:18:42.127267 2016] [:error] [pid 30018] [client 78.178.8.189:64683]   File "/usr/lib/python2.7/dist-packages/MySQLdb/__init__.py", line 81, in Connect, referer: https://www.facebook.com/
[Tue Apr 19 12:18:42.127406 2016] [:error] [pid 30018] [client 78.178.8.189:64683]     return Connection(*args, **kwargs), referer: https://www.facebook.com/
[Tue Apr 19 12:18:42.127438 2016] [:error] [pid 30018] [client 78.178.8.189:64683]   File "/usr/lib/python2.7/dist-packages/MySQLdb/connections.py", line 187, in __init__, referer: https://www.facebook.com/
[Tue Apr 19 12:18:42.127671 2016] [:error] [pid 30018] [client 78.178.8.189:64683]     super(Connection, self).__init__(*args, **kwargs2), referer: https://www.facebook.com/
[Tue Apr 19 12:18:42.127752 2016] [:error] [pid 30018] [client 78.178.8.189:64683] OperationalError: (1045, "Access denied for user 'root'@'localhost' (using password: NO)"), referer: https://www.facebook.com/
[Tue Apr 19 12:18:46.719261 2016] [:error] [pid 29988] [client 78.178.8.189:64685] mod_wsgi (pid=29988): Target WSGI script '/home/muslu/django/djangohata/djangohata/wsgi.py' cannot be loaded as Python module., referer: https://www.facebook.com/
[Tue Apr 19 12:18:46.719352 2016] [:error] [pid 29988] [client 78.178.8.189:64685] mod_wsgi (pid=29988): Exception occurred processing WSGI script '/home/muslu/django/djangohata/djangohata/wsgi.py'., referer: https://www.facebook.com/
[Tue Apr 19 12:18:46.719472 2016] [:error] [pid 29988] [client 78.178.8.189:64685] Traceback (most recent call last):, referer: https://www.facebook.com/
[Tue Apr 19 12:18:46.719518 2016] [:error] [pid 29988] [client 78.178.8.189:64685]   File "/home/muslu/django/djangohata/djangohata/wsgi.py", line 12, in <module>, referer: https://www.facebook.com/
[Tue Apr 19 12:18:46.719607 2016] [:error] [pid 29988] [client 78.178.8.189:64685]     application = get_wsgi_application(), referer: https://www.facebook.com/
[Tue Apr 19 12:18:46.719634 2016] [:error] [pid 29988] [client 78.178.8.189:64685]   File "/usr/local/lib/python2.7/dist-packages/django/core/wsgi.py", line 14, in get_wsgi_application, referer: https://www.facebook.com/
[Tue Apr 19 12:18:46.719666 2016] [:error] [pid 29988] [client 78.178.8.189:64685]     django.setup(), referer: https://www.facebook.com/
[Tue Apr 19 12:18:46.719682 2016] [:error] [pid 29988] [client 78.178.8.189:64685]   File "/usr/local/lib/python2.7/dist-packages/django/__init__.py", line 18, in setup, referer: https://www.facebook.com/
[Tue Apr 19 12:18:46.719703 2016] [:error] [pid 29988] [client 78.178.8.189:64685]     apps.populate(settings.INSTALLED_APPS), referer: https://www.facebook.com/
[Tue Apr 19 12:18:46.719723 2016] [:error] [pid 29988] [client 78.178.8.189:64685]   File "/usr/local/lib/python2.7/dist-packages/django/apps/registry.py", line 78, in populate, referer: https://www.facebook.com/
[Tue Apr 19 12:18:46.719750 2016] [:error] [pid 29988] [client 78.178.8.189:64685]     raise RuntimeError("populate() isn't reentrant"), referer: https://www.facebook.com/
[Tue Apr 19 12:18:46.719774 2016] [:error] [pid 29988] [client 78.178.8.189:64685] RuntimeError: populate() isn't reentrant, referer: https://www.facebook.com/
[Tue Apr 19 12:18:49.214813 2016] [:error] [pid 30017] [client 78.178.8.189:64684] mod_wsgi (pid=30017): Target WSGI script '/home/muslu/django/djangohata/djangohata/wsgi.py' cannot be loaded as Python module., referer: https://www.facebook.com/
[Tue Apr 19 12:18:49.214892 2016] [:error] [pid 30017] [client 78.178.8.189:64684] mod_wsgi (pid=30017): Exception occurred processing WSGI script '/home/muslu/django/djangohata/djangohata/wsgi.py'., referer: https://www.facebook.com/
[Tue Apr 19 12:18:49.214939 2016] [:error] [pid 30017] [client 78.178.8.189:64684] Traceback (most recent call last):, referer: https://www.facebook.com/
[Tue Apr 19 12:18:49.214983 2016] [:error] [pid 30017] [client 78.178.8.189:64684]   File "/home/muslu/django/djangohata/djangohata/wsgi.py", line 12, in <module>, referer: https://www.facebook.com/
[Tue Apr 19 12:18:49.215068 2016] [:error] [pid 30017] [client 78.178.8.189:64684]     application = get_wsgi_application(), referer: https://www.facebook.com/
[Tue Apr 19 12:18:49.215100 2016] [:error] [pid 30017] [client 78.178.8.189:64684]   File "/usr/local/lib/python2.7/dist-packages/django/core/wsgi.py", line 14, in get_wsgi_application, referer: https://www.facebook.com/
[Tue Apr 19 12:18:49.215138 2016] [:error] [pid 30017] [client 78.178.8.189:64684]     django.setup(), referer: https://www.facebook.com/
[Tue Apr 19 12:18:49.215166 2016] [:error] [pid 30017] [client 78.178.8.189:64684]   File "/usr/local/lib/python2.7/dist-packages/django/__init__.py", line 17, in setup, referer: https://www.facebook.com/
[Tue Apr 19 12:18:49.215206 2016] [:error] [pid 30017] [client 78.178.8.189:64684]     configure_logging(settings.LOGGING_CONFIG, settings.LOGGING), referer: https://www.facebook.com/
[Tue Apr 19 12:18:49.215258 2016] [:error] [pid 30017] [client 78.178.8.189:64684]   File "/usr/local/lib/python2.7/dist-packages/django/conf/__init__.py", line 48, in __getattr__, referer: https://www.facebook.com/
[Tue Apr 19 12:18:49.215301 2016] [:error] [pid 30017] [client 78.178.8.189:64684]     self._setup(name), referer: https://www.facebook.com/
[Tue Apr 19 12:18:49.215324 2016] [:error] [pid 30017] [client 78.178.8.189:64684]   File "/usr/local/lib/python2.7/dist-packages/django/conf/__init__.py", line 44, in _setup, referer: https://www.facebook.com/
[Tue Apr 19 12:18:49.215360 2016] [:error] [pid 30017] [client 78.178.8.189:64684]     self._wrapped = Settings(settings_module), referer: https://www.facebook.com/
[Tue Apr 19 12:18:49.215382 2016] [:error] [pid 30017] [client 78.178.8.189:64684]   File "/usr/local/lib/python2.7/dist-packages/django/conf/__init__.py", line 92, in __init__, referer: https://www.facebook.com/
[Tue Apr 19 12:18:49.215414 2016] [:error] [pid 30017] [client 78.178.8.189:64684]     mod = importlib.import_module(self.SETTINGS_MODULE), referer: https://www.facebook.com/
[Tue Apr 19 12:18:49.215435 2016] [:error] [pid 30017] [client 78.178.8.189:64684]   File "/usr/lib/python2.7/importlib/__init__.py", line 37, in import_module, referer: https://www.facebook.com/
[Tue Apr 19 12:18:49.215470 2016] [:error] [pid 30017] [client 78.178.8.189:64684]     __import__(name), referer: https://www.facebook.com/
[Tue Apr 19 12:18:49.215527 2016] [:error] [pid 30017] [client 78.178.8.189:64684] ImportError: No module named grafsoncom.settings, referer: https://www.facebook.com/
[Tue Apr 19 12:18:49.481140 2016] [:error] [pid 29989] [client 78.178.8.189:64687] mod_wsgi (pid=29989): Target WSGI script '/home/muslu/django/djangohata/djangohata/wsgi.py' cannot be loaded as Python module., referer: https://www.facebook.com/
[Tue Apr 19 12:18:49.481197 2016] [:error] [pid 29989] [client 78.178.8.189:64687] mod_wsgi (pid=29989): Exception occurred processing WSGI script '/home/muslu/django/djangohata/djangohata/wsgi.py'., referer: https://www.facebook.com/
[Tue Apr 19 12:18:49.481226 2016] [:error] [pid 29989] [client 78.178.8.189:64687] Traceback (most recent call last):, referer: https://www.facebook.com/
[Tue Apr 19 12:18:49.481256 2016] [:error] [pid 29989] [client 78.178.8.189:64687]   File "/home/muslu/django/djangohata/djangohata/wsgi.py", line 12, in <module>, referer: https://www.facebook.com/
[Tue Apr 19 12:18:49.481318 2016] [:error] [pid 29989] [client 78.178.8.189:64687]     application = get_wsgi_application(), referer: https://www.facebook.com/
[Tue Apr 19 12:18:49.481336 2016] [:error] [pid 29989] [client 78.178.8.189:64687]   File "/usr/local/lib/python2.7/dist-packages/django/core/wsgi.py", line 14, in get_wsgi_application, referer: https://www.facebook.com/
[Tue Apr 19 12:18:49.481363 2016] [:error] [pid 29989] [client 78.178.8.189:64687]     django.setup(), referer: https://www.facebook.com/
[Tue Apr 19 12:18:49.481377 2016] [:error] [pid 29989] [client 78.178.8.189:64687]   File "/usr/local/lib/python2.7/dist-packages/django/__init__.py", line 18, in setup, referer: https://www.facebook.com/
[Tue Apr 19 12:18:49.481397 2016] [:error] [pid 29989] [client 78.178.8.189:64687]     apps.populate(settings.INSTALLED_APPS), referer: https://www.facebook.com/
[Tue Apr 19 12:18:49.481411 2016] [:error] [pid 29989] [client 78.178.8.189:64687]   File "/usr/local/lib/python2.7/dist-packages/django/apps/registry.py", line 78, in populate, referer: https://www.facebook.com/
[Tue Apr 19 12:18:49.481438 2016] [:error] [pid 29989] [client 78.178.8.189:64687]     raise RuntimeError("populate() isn't reentrant"), referer: https://www.facebook.com/
[Tue Apr 19 12:18:49.481474 2016] [:error] [pid 29989] [client 78.178.8.189:64687] RuntimeError: populate() isn't reentrant, referer: https://www.facebook.com/
[Tue Apr 19 12:18:49.813029 2016] [:error] [pid 30022] [client 78.178.8.189:64688] mod_wsgi (pid=30022): Target WSGI script '/home/muslu/django/djangohata/djangohata/wsgi.py' cannot be loaded as Python module., referer: https://www.facebook.com/
[Tue Apr 19 12:18:49.813188 2016] [:error] [pid 30022] [client 78.178.8.189:64688] mod_wsgi (pid=30022): Exception occurred processing WSGI script '/home/muslu/django/djangohata/djangohata/wsgi.py'., referer: https://www.facebook.com/
[Tue Apr 19 12:18:49.813232 2016] [:error] [pid 30022] [client 78.178.8.189:64688] Traceback (most recent call last):, referer: https://www.facebook.com/
[Tue Apr 19 12:18:49.813269 2016] [:error] [pid 30022] [client 78.178.8.189:64688]   File "/home/muslu/django/djangohata/djangohata/wsgi.py", line 12, in <module>, referer: https://www.facebook.com/
[Tue Apr 19 12:18:49.813320 2016] [:error] [pid 30022] [client 78.178.8.189:64688]     application = get_wsgi_application(), referer: https://www.facebook.com/
[Tue Apr 19 12:18:49.813341 2016] [:error] [pid 30022] [client 78.178.8.189:64688]   File "/usr/local/lib/python2.7/dist-packages/django/core/wsgi.py", line 14, in get_wsgi_application, referer: https://www.facebook.com/
[Tue Apr 19 12:18:49.813370 2016] [:error] [pid 30022] [client 78.178.8.189:64688]     django.setup(), referer: https://www.facebook.com/
[Tue Apr 19 12:18:49.813384 2016] [:error] [pid 30022] [client 78.178.8.189:64688]   File "/usr/local/lib/python2.7/dist-packages/django/__init__.py", line 18, in setup, referer: https://www.facebook.com/
[Tue Apr 19 12:18:49.813404 2016] [:error] [pid 30022] [client 78.178.8.189:64688]     apps.populate(settings.INSTALLED_APPS), referer: https://www.facebook.com/
[Tue Apr 19 12:18:49.813417 2016] [:error] [pid 30022] [client 78.178.8.189:64688]   File "/usr/local/lib/python2.7/dist-packages/django/apps/registry.py", line 78, in populate, referer: https://www.facebook.com/
[Tue Apr 19 12:18:49.813438 2016] [:error] [pid 30022] [client 78.178.8.189:64688]     raise RuntimeError("populate() isn't reentrant"), referer: https://www.facebook.com/
[Tue Apr 19 12:18:49.813467 2016] [:error] [pid 30022] [client 78.178.8.189:64688] RuntimeError: populate() isn't reentrant, referer: https://www.facebook.com/
[Tue Apr 19 12:19:03.205577 2016] [:error] [pid 29988] [client 78.178.8.189:64690] mod_wsgi (pid=29988): Target WSGI script '/home/muslu/django/djangohata/djangohata/wsgi.py' cannot be loaded as Python module., referer: https://www.facebook.com/
[Tue Apr 19 12:19:03.206868 2016] [:error] [pid 29988] [client 78.178.8.189:64690] mod_wsgi (pid=29988): Exception occurred processing WSGI script '/home/muslu/django/djangohata/djangohata/wsgi.py'., referer: https://www.facebook.com/
[Tue Apr 19 12:19:03.207311 2016] [:error] [pid 29988] [client 78.178.8.189:64690] Traceback (most recent call last):, referer: https://www.facebook.com/
[Tue Apr 19 12:19:03.207381 2016] [:error] [pid 29988] [client 78.178.8.189:64690]   File "/home/muslu/django/djangohata/djangohata/wsgi.py", line 12, in <module>, referer: https://www.facebook.com/
[Tue Apr 19 12:19:03.209386 2016] [:error] [pid 29988] [client 78.178.8.189:64690]     application = get_wsgi_application(), referer: https://www.facebook.com/
[Tue Apr 19 12:19:03.209472 2016] [:error] [pid 29988] [client 78.178.8.189:64690]   File "/usr/local/lib/python2.7/dist-packages/django/core/wsgi.py", line 14, in get_wsgi_application, referer: https://www.facebook.com/
[Tue Apr 19 12:19:03.209541 2016] [:error] [pid 29988] [client 78.178.8.189:64690]     django.setup(), referer: https://www.facebook.com/
[Tue Apr 19 12:19:03.209572 2016] [:error] [pid 29988] [client 78.178.8.189:64690]   File "/usr/local/lib/python2.7/dist-packages/django/__init__.py", line 18, in setup, referer: https://www.facebook.com/
[Tue Apr 19 12:19:03.209611 2016] [:error] [pid 29988] [client 78.178.8.189:64690]     apps.populate(settings.INSTALLED_APPS), referer: https://www.facebook.com/
[Tue Apr 19 12:19:03.209637 2016] [:error] [pid 29988] [client 78.178.8.189:64690]   File "/usr/local/lib/python2.7/dist-packages/django/apps/registry.py", line 78, in populate, referer: https://www.facebook.com/
[Tue Apr 19 12:19:03.209712 2016] [:error] [pid 29988] [client 78.178.8.189:64690]     raise RuntimeError("populate() isn't reentrant"), referer: https://www.facebook.com/
[Tue Apr 19 12:19:03.209788 2016] [:error] [pid 29988] [client 78.178.8.189:64690] RuntimeError: populate() isn't reentrant, referer: https://www.facebook.com/
[Tue Apr 19 12:19:09.679275 2016] [:error] [pid 30019] [client 78.178.8.189:64692] mod_wsgi (pid=30019): Target WSGI script '/home/muslu/django/djangohata/djangohata/wsgi.py' cannot be loaded as Python module., referer: https://www.facebook.com/
[Tue Apr 19 12:19:09.679339 2016] [:error] [pid 30019] [client 78.178.8.189:64692] mod_wsgi (pid=30019): Exception occurred processing WSGI script '/home/muslu/django/djangohata/djangohata/wsgi.py'., referer: https://www.facebook.com/
[Tue Apr 19 12:19:09.679395 2016] [:error] [pid 30019] [client 78.178.8.189:64692] Traceback (most recent call last):, referer: https://www.facebook.com/
[Tue Apr 19 12:19:09.679431 2016] [:error] [pid 30019] [client 78.178.8.189:64692]   File "/home/muslu/django/djangohata/djangohata/wsgi.py", line 12, in <module>, referer: https://www.facebook.com/
[Tue Apr 19 12:19:09.679529 2016] [:error] [pid 30019] [client 78.178.8.189:64692]     application = get_wsgi_application(), referer: https://www.facebook.com/
[Tue Apr 19 12:19:09.679560 2016] [:error] [pid 30019] [client 78.178.8.189:64692]   File "/usr/local/lib/python2.7/dist-packages/django/core/wsgi.py", line 14, in get_wsgi_application, referer: https://www.facebook.com/
[Tue Apr 19 12:19:09.679652 2016] [:error] [pid 30019] [client 78.178.8.189:64692]     django.setup(), referer: https://www.facebook.com/
[Tue Apr 19 12:19:09.679675 2016] [:error] [pid 30019] [client 78.178.8.189:64692]   File "/usr/local/lib/python2.7/dist-packages/django/__init__.py", line 17, in setup, referer: https://www.facebook.com/
[Tue Apr 19 12:19:09.679736 2016] [:error] [pid 30019] [client 78.178.8.189:64692]     configure_logging(settings.LOGGING_CONFIG, settings.LOGGING), referer: https://www.facebook.com/
[Tue Apr 19 12:19:09.679771 2016] [:error] [pid 30019] [client 78.178.8.189:64692]   File "/usr/local/lib/python2.7/dist-packages/django/conf/__init__.py", line 48, in __getattr__, referer: https://www.facebook.com/
[Tue Apr 19 12:19:09.679918 2016] [:error] [pid 30019] [client 78.178.8.189:64692]     self._setup(name), referer: https://www.facebook.com/
[Tue Apr 19 12:19:09.679938 2016] [:error] [pid 30019] [client 78.178.8.189:64692]   File "/usr/local/lib/python2.7/dist-packages/django/conf/__init__.py", line 44, in _setup, referer: https://www.facebook.com/
[Tue Apr 19 12:19:09.679969 2016] [:error] [pid 30019] [client 78.178.8.189:64692]     self._wrapped = Settings(settings_module), referer: https://www.facebook.com/
[Tue Apr 19 12:19:09.679994 2016] [:error] [pid 30019] [client 78.178.8.189:64692]   File "/usr/local/lib/python2.7/dist-packages/django/conf/__init__.py", line 92, in __init__, referer: https://www.facebook.com/
[Tue Apr 19 12:19:09.680031 2016] [:error] [pid 30019] [client 78.178.8.189:64692]     mod = importlib.import_module(self.SETTINGS_MODULE), referer: https://www.facebook.com/
[Tue Apr 19 12:19:09.680048 2016] [:error] [pid 30019] [client 78.178.8.189:64692]   File "/usr/lib/python2.7/importlib/__init__.py", line 37, in import_module, referer: https://www.facebook.com/
[Tue Apr 19 12:19:09.680116 2016] [:error] [pid 30019] [client 78.178.8.189:64692]     __import__(name), referer: https://www.facebook.com/
[Tue Apr 19 12:19:09.680159 2016] [:error] [pid 30019] [client 78.178.8.189:64692] ImportError: No module named izmirteknikservis.settings, referer: https://www.facebook.com/
[Tue Apr 19 12:19:11.686174 2016] [:error] [pid 29986] [client 78.178.8.189:64693] mod_wsgi (pid=29986): Target WSGI script '/home/muslu/django/djangohata/djangohata/wsgi.py' cannot be loaded as Python module., referer: https://www.facebook.com/
[Tue Apr 19 12:19:11.686233 2016] [:error] [pid 29986] [client 78.178.8.189:64693] mod_wsgi (pid=29986): Exception occurred processing WSGI script '/home/muslu/django/djangohata/djangohata/wsgi.py'., referer: https://www.facebook.com/
[Tue Apr 19 12:19:11.686280 2016] [:error] [pid 29986] [client 78.178.8.189:64693] Traceback (most recent call last):, referer: https://www.facebook.com/
[Tue Apr 19 12:19:11.686324 2016] [:error] [pid 29986] [client 78.178.8.189:64693]   File "/home/muslu/django/djangohata/djangohata/wsgi.py", line 12, in <module>, referer: https://www.facebook.com/
[Tue Apr 19 12:19:11.686451 2016] [:error] [pid 29986] [client 78.178.8.189:64693]     application = get_wsgi_application(), referer: https://www.facebook.com/
[Tue Apr 19 12:19:11.686477 2016] [:error] [pid 29986] [client 78.178.8.189:64693]   File "/usr/local/lib/python2.7/dist-packages/django/core/wsgi.py", line 14, in get_wsgi_application, referer: https://www.facebook.com/
[Tue Apr 19 12:19:11.686555 2016] [:error] [pid 29986] [client 78.178.8.189:64693]     django.setup(), referer: https://www.facebook.com/
[Tue Apr 19 12:19:11.686577 2016] [:error] [pid 29986] [client 78.178.8.189:64693]   File "/usr/local/lib/python2.7/dist-packages/django/__init__.py", line 17, in setup, referer: https://www.facebook.com/
[Tue Apr 19 12:19:11.686658 2016] [:error] [pid 29986] [client 78.178.8.189:64693]     configure_logging(settings.LOGGING_CONFIG, settings.LOGGING), referer: https://www.facebook.com/
[Tue Apr 19 12:19:11.686682 2016] [:error] [pid 29986] [client 78.178.8.189:64693]   File "/usr/local/lib/python2.7/dist-packages/django/conf/__init__.py", line 48, in __getattr__, referer: https://www.facebook.com/
[Tue Apr 19 12:19:11.686886 2016] [:error] [pid 29986] [client 78.178.8.189:64693]     self._setup(name), referer: https://www.facebook.com/
[Tue Apr 19 12:19:11.686924 2016] [:error] [pid 29986] [client 78.178.8.189:64693]   File "/usr/local/lib/python2.7/dist-packages/django/conf/__init__.py", line 44, in _setup, referer: https://www.facebook.com/
[Tue Apr 19 12:19:11.686953 2016] [:error] [pid 29986] [client 78.178.8.189:64693]     self._wrapped = Settings(settings_module), referer: https://www.facebook.com/
[Tue Apr 19 12:19:11.686967 2016] [:error] [pid 29986] [client 78.178.8.189:64693]   File "/usr/local/lib/python2.7/dist-packages/django/conf/__init__.py", line 92, in __init__, referer: https://www.facebook.com/
[Tue Apr 19 12:19:11.686986 2016] [:error] [pid 29986] [client 78.178.8.189:64693]     mod = importlib.import_module(self.SETTINGS_MODULE), referer: https://www.facebook.com/
[Tue Apr 19 12:19:11.686998 2016] [:error] [pid 29986] [client 78.178.8.189:64693]   File "/usr/lib/python2.7/importlib/__init__.py", line 37, in import_module, referer: https://www.facebook.com/
[Tue Apr 19 12:19:11.687060 2016] [:error] [pid 29986] [client 78.178.8.189:64693]     __import__(name), referer: https://www.facebook.com/
[Tue Apr 19 12:19:11.687087 2016] [:error] [pid 29986] [client 78.178.8.189:64693] ImportError: No module named izmirteknikservis.settings, referer: https://www.facebook.com/
[Tue Apr 19 12:19:13.949406 2016] [:error] [pid 30022] [client 78.178.8.189:64694] mod_wsgi (pid=30022): Target WSGI script '/home/muslu/django/djangohata/djangohata/wsgi.py' cannot be loaded as Python module., referer: https://www.facebook.com/
[Tue Apr 19 12:19:13.949464 2016] [:error] [pid 30022] [client 78.178.8.189:64694] mod_wsgi (pid=30022): Exception occurred processing WSGI script '/home/muslu/django/djangohata/djangohata/wsgi.py'., referer: https://www.facebook.com/
[Tue Apr 19 12:19:13.949493 2016] [:error] [pid 30022] [client 78.178.8.189:64694] Traceback (most recent call last):, referer: https://www.facebook.com/
[Tue Apr 19 12:19:13.949582 2016] [:error] [pid 30022] [client 78.178.8.189:64694]   File "/home/muslu/django/djangohata/djangohata/wsgi.py", line 12, in <module>, referer: https://www.facebook.com/
[Tue Apr 19 12:19:13.949658 2016] [:error] [pid 30022] [client 78.178.8.189:64694]     application = get_wsgi_application(), referer: https://www.facebook.com/
[Tue Apr 19 12:19:13.949688 2016] [:error] [pid 30022] [client 78.178.8.189:64694]   File "/usr/local/lib/python2.7/dist-packages/django/core/wsgi.py", line 14, in get_wsgi_application, referer: https://www.facebook.com/
[Tue Apr 19 12:19:13.949738 2016] [:error] [pid 30022] [client 78.178.8.189:64694]     django.setup(), referer: https://www.facebook.com/
[Tue Apr 19 12:19:13.949754 2016] [:error] [pid 30022] [client 78.178.8.189:64694]   File "/usr/local/lib/python2.7/dist-packages/django/__init__.py", line 18, in setup, referer: https://www.facebook.com/
[Tue Apr 19 12:19:13.949774 2016] [:error] [pid 30022] [client 78.178.8.189:64694]     apps.populate(settings.INSTALLED_APPS), referer: https://www.facebook.com/
[Tue Apr 19 12:19:13.949787 2016] [:error] [pid 30022] [client 78.178.8.189:64694]   File "/usr/local/lib/python2.7/dist-packages/django/apps/registry.py", line 78, in populate, referer: https://www.facebook.com/
[Tue Apr 19 12:19:13.949808 2016] [:error] [pid 30022] [client 78.178.8.189:64694]     raise RuntimeError("populate() isn't reentrant"), referer: https://www.facebook.com/
[Tue Apr 19 12:19:13.949832 2016] [:error] [pid 30022] [client 78.178.8.189:64694] RuntimeError: populate() isn't reentrant, referer: https://www.facebook.com/
[Tue Apr 19 12:19:15.926759 2016] [:error] [pid 29988] [client 78.178.8.189:64695] mod_wsgi (pid=29988): Target WSGI script '/home/muslu/django/djangohata/djangohata/wsgi.py' cannot be loaded as Python module., referer: https://www.facebook.com/
[Tue Apr 19 12:19:15.926901 2016] [:error] [pid 29988] [client 78.178.8.189:64695] mod_wsgi (pid=29988): Exception occurred processing WSGI script '/home/muslu/django/djangohata/djangohata/wsgi.py'., referer: https://www.facebook.com/
[Tue Apr 19 12:19:15.926945 2016] [:error] [pid 29988] [client 78.178.8.189:64695] Traceback (most recent call last):, referer: https://www.facebook.com/
[Tue Apr 19 12:19:15.926977 2016] [:error] [pid 29988] [client 78.178.8.189:64695]   File "/home/muslu/django/djangohata/djangohata/wsgi.py", line 12, in <module>, referer: https://www.facebook.com/
[Tue Apr 19 12:19:15.927033 2016] [:error] [pid 29988] [client 78.178.8.189:64695]     application = get_wsgi_application(), referer: https://www.facebook.com/
[Tue Apr 19 12:19:15.927051 2016] [:error] [pid 29988] [client 78.178.8.189:64695]   File "/usr/local/lib/python2.7/dist-packages/django/core/wsgi.py", line 14, in get_wsgi_application, referer: https://www.facebook.com/
[Tue Apr 19 12:19:15.927075 2016] [:error] [pid 29988] [client 78.178.8.189:64695]     django.setup(), referer: https://www.facebook.com/
[Tue Apr 19 12:19:15.927089 2016] [:error] [pid 29988] [client 78.178.8.189:64695]   File "/usr/local/lib/python2.7/dist-packages/django/__init__.py", line 18, in setup, referer: https://www.facebook.com/
[Tue Apr 19 12:19:15.927109 2016] [:error] [pid 29988] [client 78.178.8.189:64695]     apps.populate(settings.INSTALLED_APPS), referer: https://www.facebook.com/
[Tue Apr 19 12:19:15.927122 2016] [:error] [pid 29988] [client 78.178.8.189:64695]   File "/usr/local/lib/python2.7/dist-packages/django/apps/registry.py", line 78, in populate, referer: https://www.facebook.com/
[Tue Apr 19 12:19:15.927142 2016] [:error] [pid 29988] [client 78.178.8.189:64695]     raise RuntimeError("populate() isn't reentrant"), referer: https://www.facebook.com/
[Tue Apr 19 12:19:15.927165 2016] [:error] [pid 29988] [client 78.178.8.189:64695] RuntimeError: populate() isn't reentrant, referer: https://www.facebook.com/
[Tue Apr 19 12:23:05.898828 2016] [:error] [pid 29988] [client 66.249.78.202:33019] mod_wsgi (pid=29988): Target WSGI script '/home/muslu/django/djangohata/djangohata/wsgi.py' cannot be loaded as Python module.
[Tue Apr 19 12:23:05.898903 2016] [:error] [pid 29988] [client 66.249.78.202:33019] mod_wsgi (pid=29988): Exception occurred processing WSGI script '/home/muslu/django/djangohata/djangohata/wsgi.py'.
[Tue Apr 19 12:23:05.898963 2016] [:error] [pid 29988] [client 66.249.78.202:33019] Traceback (most recent call last):
[Tue Apr 19 12:23:05.899884 2016] [:error] [pid 29988] [client 66.249.78.202:33019]   File "/home/muslu/django/djangohata/djangohata/wsgi.py", line 12, in <module>
[Tue Apr 19 12:23:05.900057 2016] [:error] [pid 29988] [client 66.249.78.202:33019]     application = get_wsgi_application()
[Tue Apr 19 12:23:05.900098 2016] [:error] [pid 29988] [client 66.249.78.202:33019]   File "/usr/local/lib/python2.7/dist-packages/django/core/wsgi.py", line 14, in get_wsgi_application
[Tue Apr 19 12:23:05.900151 2016] [:error] [pid 29988] [client 66.249.78.202:33019]     django.setup()
[Tue Apr 19 12:23:05.900182 2016] [:error] [pid 29988] [client 66.249.78.202:33019]   File "/usr/local/lib/python2.7/dist-packages/django/__init__.py", line 18, in setup
[Tue Apr 19 12:23:05.900223 2016] [:error] [pid 29988] [client 66.249.78.202:33019]     apps.populate(settings.INSTALLED_APPS)
[Tue Apr 19 12:23:05.900248 2016] [:error] [pid 29988] [client 66.249.78.202:33019]   File "/usr/local/lib/python2.7/dist-packages/django/apps/registry.py", line 78, in populate
[Tue Apr 19 12:23:05.900287 2016] [:error] [pid 29988] [client 66.249.78.202:33019]     raise RuntimeError("populate() isn't reentrant")
[Tue Apr 19 12:23:05.900324 2016] [:error] [pid 29988] [client 66.249.78.202:33019] RuntimeError: populate() isn't reentrant
[Tue Apr 19 12:28:59.388825 2016] [:error] [pid 29989] [client 66.249.66.124:61099] mod_wsgi (pid=29989): Target WSGI script '/home/muslu/django/djangohata/djangohata/wsgi.py' cannot be loaded as Python module.
[Tue Apr 19 12:28:59.388892 2016] [:error] [pid 29989] [client 66.249.66.124:61099] mod_wsgi (pid=29989): Exception occurred processing WSGI script '/home/muslu/django/djangohata/djangohata/wsgi.py'.
[Tue Apr 19 12:28:59.388949 2016] [:error] [pid 29989] [client 66.249.66.124:61099] Traceback (most recent call last):
[Tue Apr 19 12:28:59.389005 2016] [:error] [pid 29989] [client 66.249.66.124:61099]   File "/home/muslu/django/djangohata/djangohata/wsgi.py", line 12, in <module>
[Tue Apr 19 12:28:59.389176 2016] [:error] [pid 29989] [client 66.249.66.124:61099]     application = get_wsgi_application()
[Tue Apr 19 12:28:59.389210 2016] [:error] [pid 29989] [client 66.249.66.124:61099]   File "/usr/local/lib/python2.7/dist-packages/django/core/wsgi.py", line 14, in get_wsgi_application
[Tue Apr 19 12:28:59.389251 2016] [:error] [pid 29989] [client 66.249.66.124:61099]     django.setup()
[Tue Apr 19 12:28:59.389276 2016] [:error] [pid 29989] [client 66.249.66.124:61099]   File "/usr/local/lib/python2.7/dist-packages/django/__init__.py", line 18, in setup
[Tue Apr 19 12:28:59.389311 2016] [:error] [pid 29989] [client 66.249.66.124:61099]     apps.populate(settings.INSTALLED_APPS)
[Tue Apr 19 12:28:59.389333 2016] [:error] [pid 29989] [client 66.249.66.124:61099]   File "/usr/local/lib/python2.7/dist-packages/django/apps/registry.py", line 78, in populate
[Tue Apr 19 12:28:59.389371 2016] [:error] [pid 29989] [client 66.249.66.124:61099]     raise RuntimeError("populate() isn't reentrant")
[Tue Apr 19 12:28:59.389406 2016] [:error] [pid 29989] [client 66.249.66.124:61099] RuntimeError: populate() isn't reentrant
[Tue Apr 19 12:30:14.658349 2016] [:error] [pid 29989] [client 78.178.217.66:51718] mod_wsgi (pid=29989): Target WSGI script '/home/muslu/django/djangohata/djangohata/wsgi.py' cannot be loaded as Python module., referer: http://www.pythome.com/django/commanderror/s-are-you-sure-your-installed_apps-setting-is-correct-e/
[Tue Apr 19 12:30:14.658398 2016] [:error] [pid 29989] [client 78.178.217.66:51718] mod_wsgi (pid=29989): Exception occurred processing WSGI script '/home/muslu/django/djangohata/djangohata/wsgi.py'., referer: http://www.pythome.com/django/commanderror/s-are-you-sure-your-installed_apps-setting-is-correct-e/
[Tue Apr 19 12:30:14.658452 2016] [:error] [pid 29989] [client 78.178.217.66:51718] Traceback (most recent call last):, referer: http://www.pythome.com/django/commanderror/s-are-you-sure-your-installed_apps-setting-is-correct-e/
[Tue Apr 19 12:30:14.658487 2016] [:error] [pid 29989] [client 78.178.217.66:51718]   File "/home/muslu/django/djangohata/djangohata/wsgi.py", line 12, in <module>, referer: http://www.pythome.com/django/commanderror/s-are-you-sure-your-installed_apps-setting-is-correct-e/
[Tue Apr 19 12:30:14.658696 2016] [:error] [pid 29989] [client 78.178.217.66:51718]     application = get_wsgi_application(), referer: http://www.pythome.com/django/commanderror/s-are-you-sure-your-installed_apps-setting-is-correct-e/
[Tue Apr 19 12:30:14.658775 2016] [:error] [pid 29989] [client 78.178.217.66:51718]   File "/usr/local/lib/python2.7/dist-packages/django/core/wsgi.py", line 14, in get_wsgi_application, referer: http://www.pythome.com/django/commanderror/s-are-you-sure-your-installed_apps-setting-is-correct-e/
[Tue Apr 19 12:30:14.658820 2016] [:error] [pid 29989] [client 78.178.217.66:51718]     django.setup(), referer: http://www.pythome.com/django/commanderror/s-are-you-sure-your-installed_apps-setting-is-correct-e/
[Tue Apr 19 12:30:14.658842 2016] [:error] [pid 29989] [client 78.178.217.66:51718]   File "/usr/local/lib/python2.7/dist-packages/django/__init__.py", line 18, in setup, referer: http://www.pythome.com/django/commanderror/s-are-you-sure-your-installed_apps-setting-is-correct-e/
[Tue Apr 19 12:30:14.658890 2016] [:error] [pid 29989] [client 78.178.217.66:51718]     apps.populate(settings.INSTALLED_APPS), referer: http://www.pythome.com/django/commanderror/s-are-you-sure-your-installed_apps-setting-is-correct-e/
[Tue Apr 19 12:30:14.658911 2016] [:error] [pid 29989] [client 78.178.217.66:51718]   File "/usr/local/lib/python2.7/dist-packages/django/apps/registry.py", line 78, in populate, referer: http://www.pythome.com/django/commanderror/s-are-you-sure-your-installed_apps-setting-is-correct-e/
[Tue Apr 19 12:30:14.658946 2016] [:error] [pid 29989] [client 78.178.217.66:51718]     raise RuntimeError("populate() isn't reentrant"), referer: http://www.pythome.com/django/commanderror/s-are-you-sure-your-installed_apps-setting-is-correct-e/
[Tue Apr 19 12:30:14.658981 2016] [:error] [pid 29989] [client 78.178.217.66:51718] RuntimeError: populate() isn't reentrant, referer: http://www.pythome.com/django/commanderror/s-are-you-sure-your-installed_apps-setting-is-correct-e/
[Tue Apr 19 12:32:21.501423 2016] [:error] [pid 30021] [client 78.176.190.30:54192] mod_wsgi (pid=30021): Target WSGI script '/home/muslu/django/djangohata/djangohata/wsgi.py' cannot be loaded as Python module., referer: https://www.facebook.com/
[Tue Apr 19 12:32:21.501473 2016] [:error] [pid 30021] [client 78.176.190.30:54192] mod_wsgi (pid=30021): Exception occurred processing WSGI script '/home/muslu/django/djangohata/djangohata/wsgi.py'., referer: https://www.facebook.com/
[Tue Apr 19 12:32:21.501516 2016] [:error] [pid 30021] [client 78.176.190.30:54192] Traceback (most recent call last):, referer: https://www.facebook.com/
[Tue Apr 19 12:32:21.501558 2016] [:error] [pid 30021] [client 78.176.190.30:54192]   File "/home/muslu/django/djangohata/djangohata/wsgi.py", line 12, in <module>, referer: https://www.facebook.com/
[Tue Apr 19 12:32:21.501679 2016] [:error] [pid 30021] [client 78.176.190.30:54192]     application = get_wsgi_application(), referer: https://www.facebook.com/
[Tue Apr 19 12:32:21.501704 2016] [:error] [pid 30021] [client 78.176.190.30:54192]   File "/usr/local/lib/python2.7/dist-packages/django/core/wsgi.py", line 14, in get_wsgi_application, referer: https://www.facebook.com/
[Tue Apr 19 12:32:21.501783 2016] [:error] [pid 30021] [client 78.176.190.30:54192]     django.setup(), referer: https://www.facebook.com/
[Tue Apr 19 12:32:21.501812 2016] [:error] [pid 30021] [client 78.176.190.30:54192]   File "/usr/local/lib/python2.7/dist-packages/django/__init__.py", line 17, in setup, referer: https://www.facebook.com/
[Tue Apr 19 12:32:21.501890 2016] [:error] [pid 30021] [client 78.176.190.30:54192]     configure_logging(settings.LOGGING_CONFIG, settings.LOGGING), referer: https://www.facebook.com/
[Tue Apr 19 12:32:21.501922 2016] [:error] [pid 30021] [client 78.176.190.30:54192]   File "/usr/local/lib/python2.7/dist-packages/django/conf/__init__.py", line 48, in __getattr__, referer: https://www.facebook.com/
[Tue Apr 19 12:32:21.502081 2016] [:error] [pid 30021] [client 78.176.190.30:54192]     self._setup(name), referer: https://www.facebook.com/
[Tue Apr 19 12:32:21.502121 2016] [:error] [pid 30021] [client 78.176.190.30:54192]   File "/usr/local/lib/python2.7/dist-packages/django/conf/__init__.py", line 44, in _setup, referer: https://www.facebook.com/
[Tue Apr 19 12:32:21.502159 2016] [:error] [pid 30021] [client 78.176.190.30:54192]     self._wrapped = Settings(settings_module), referer: https://www.facebook.com/
[Tue Apr 19 12:32:21.502183 2016] [:error] [pid 30021] [client 78.176.190.30:54192]   File "/usr/local/lib/python2.7/dist-packages/django/conf/__init__.py", line 92, in __init__, referer: https://www.facebook.com/
[Tue Apr 19 12:32:21.502218 2016] [:error] [pid 30021] [client 78.176.190.30:54192]     mod = importlib.import_module(self.SETTINGS_MODULE), referer: https://www.facebook.com/
[Tue Apr 19 12:32:21.502239 2016] [:error] [pid 30021] [client 78.176.190.30:54192]   File "/usr/lib/python2.7/importlib/__init__.py", line 37, in import_module, referer: https://www.facebook.com/
[Tue Apr 19 12:32:21.502337 2016] [:error] [pid 30021] [client 78.176.190.30:54192]     __import__(name), referer: https://www.facebook.com/
[Tue Apr 19 12:32:21.502382 2016] [:error] [pid 30021] [client 78.176.190.30:54192] ImportError: No module named grafsoncom.settings, referer: https://www.facebook.com/
[Tue Apr 19 12:34:49.376552 2016] [:error] [pid 29988] [client 194.29.137.1:60236] mod_wsgi (pid=29988): Target WSGI script '/home/muslu/django/djangohata/djangohata/wsgi.py' cannot be loaded as Python module.
[Tue Apr 19 12:34:49.376599 2016] [:error] [pid 29988] [client 194.29.137.1:60236] mod_wsgi (pid=29988): Exception occurred processing WSGI script '/home/muslu/django/djangohata/djangohata/wsgi.py'.
[Tue Apr 19 12:34:49.376717 2016] [:error] [pid 29988] [client 194.29.137.1:60236] Traceback (most recent call last):
[Tue Apr 19 12:34:49.376786 2016] [:error] [pid 29988] [client 194.29.137.1:60236]   File "/home/muslu/django/djangohata/djangohata/wsgi.py", line 12, in <module>
[Tue Apr 19 12:34:49.377013 2016] [:error] [pid 29988] [client 194.29.137.1:60236]     application = get_wsgi_application()
[Tue Apr 19 12:34:49.377041 2016] [:error] [pid 29988] [client 194.29.137.1:60236]   File "/usr/local/lib/python2.7/dist-packages/django/core/wsgi.py", line 14, in get_wsgi_application
[Tue Apr 19 12:34:49.377174 2016] [:error] [pid 29988] [client 194.29.137.1:60236]     django.setup()
[Tue Apr 19 12:34:49.377206 2016] [:error] [pid 29988] [client 194.29.137.1:60236]   File "/usr/local/lib/python2.7/dist-packages/django/__init__.py", line 18, in setup
[Tue Apr 19 12:34:49.377243 2016] [:error] [pid 29988] [client 194.29.137.1:60236]     apps.populate(settings.INSTALLED_APPS)
[Tue Apr 19 12:34:49.377265 2016] [:error] [pid 29988] [client 194.29.137.1:60236]   File "/usr/local/lib/python2.7/dist-packages/django/apps/registry.py", line 78, in populate
[Tue Apr 19 12:34:49.377312 2016] [:error] [pid 29988] [client 194.29.137.1:60236]     raise RuntimeError("populate() isn't reentrant")
[Tue Apr 19 12:34:49.377367 2016] [:error] [pid 29988] [client 194.29.137.1:60236] RuntimeError: populate() isn't reentrant
[Tue Apr 19 12:34:57.578305 2016] [:error] [pid 30135] [client 66.249.78.209:46360] mod_wsgi (pid=30135): Target WSGI script '/home/muslu/django/djangohata/djangohata/wsgi.py' cannot be loaded as Python module.
[Tue Apr 19 12:34:57.578352 2016] [:error] [pid 30135] [client 66.249.78.209:46360] mod_wsgi (pid=30135): Exception occurred processing WSGI script '/home/muslu/django/djangohata/djangohata/wsgi.py'.
[Tue Apr 19 12:34:57.578401 2016] [:error] [pid 30135] [client 66.249.78.209:46360] Traceback (most recent call last):
[Tue Apr 19 12:34:57.578441 2016] [:error] [pid 30135] [client 66.249.78.209:46360]   File "/home/muslu/django/djangohata/djangohata/wsgi.py", line 12, in <module>
[Tue Apr 19 12:34:57.578563 2016] [:error] [pid 30135] [client 66.249.78.209:46360]     application = get_wsgi_application()
[Tue Apr 19 12:34:57.578587 2016] [:error] [pid 30135] [client 66.249.78.209:46360]   File "/usr/local/lib/python2.7/dist-packages/django/core/wsgi.py", line 14, in get_wsgi_application
[Tue Apr 19 12:34:57.578680 2016] [:error] [pid 30135] [client 66.249.78.209:46360]     django.setup()
[Tue Apr 19 12:34:57.578698 2016] [:error] [pid 30135] [client 66.249.78.209:46360]   File "/usr/local/lib/python2.7/dist-packages/django/__init__.py", line 17, in setup
[Tue Apr 19 12:34:57.578747 2016] [:error] [pid 30135] [client 66.249.78.209:46360]     configure_logging(settings.LOGGING_CONFIG, settings.LOGGING)
[Tue Apr 19 12:34:57.578761 2016] [:error] [pid 30135] [client 66.249.78.209:46360]   File "/usr/local/lib/python2.7/dist-packages/django/conf/__init__.py", line 48, in __getattr__
[Tue Apr 19 12:34:57.578884 2016] [:error] [pid 30135] [client 66.249.78.209:46360]     self._setup(name)
[Tue Apr 19 12:34:57.578901 2016] [:error] [pid 30135] [client 66.249.78.209:46360]   File "/usr/local/lib/python2.7/dist-packages/django/conf/__init__.py", line 44, in _setup
[Tue Apr 19 12:34:57.578935 2016] [:error] [pid 30135] [client 66.249.78.209:46360]     self._wrapped = Settings(settings_module)
[Tue Apr 19 12:34:57.578956 2016] [:error] [pid 30135] [client 66.249.78.209:46360]   File "/usr/local/lib/python2.7/dist-packages/django/conf/__init__.py", line 92, in __init__
[Tue Apr 19 12:34:57.578986 2016] [:error] [pid 30135] [client 66.249.78.209:46360]     mod = importlib.import_module(self.SETTINGS_MODULE)
[Tue Apr 19 12:34:57.579008 2016] [:error] [pid 30135] [client 66.249.78.209:46360]   File "/usr/lib/python2.7/importlib/__init__.py", line 37, in import_module
[Tue Apr 19 12:34:57.579088 2016] [:error] [pid 30135] [client 66.249.78.209:46360]     __import__(name)
[Tue Apr 19 12:34:57.579119 2016] [:error] [pid 30135] [client 66.249.78.209:46360] ImportError: No module named eseelektrik.settings
[Tue Apr 19 12:34:58.975282 2016] [:error] [pid 29988] [client 82.222.218.244:59462] mod_wsgi (pid=29988): Target WSGI script '/home/muslu/django/djangohata/djangohata/wsgi.py' cannot be loaded as Python module., referer: https://www.facebook.com/
[Tue Apr 19 12:34:58.975317 2016] [:error] [pid 29988] [client 82.222.218.244:59462] mod_wsgi (pid=29988): Exception occurred processing WSGI script '/home/muslu/django/djangohata/djangohata/wsgi.py'., referer: https://www.facebook.com/
[Tue Apr 19 12:34:58.975345 2016] [:error] [pid 29988] [client 82.222.218.244:59462] Traceback (most recent call last):, referer: https://www.facebook.com/
[Tue Apr 19 12:34:58.975371 2016] [:error] [pid 29988] [client 82.222.218.244:59462]   File "/home/muslu/django/djangohata/djangohata/wsgi.py", line 12, in <module>, referer: https://www.facebook.com/
[Tue Apr 19 12:34:58.975404 2016] [:error] [pid 29988] [client 82.222.218.244:59462]     application = get_wsgi_application(), referer: https://www.facebook.com/
[Tue Apr 19 12:34:58.975417 2016] [:error] [pid 29988] [client 82.222.218.244:59462]   File "/usr/local/lib/python2.7/dist-packages/django/core/wsgi.py", line 14, in get_wsgi_application, referer: https://www.facebook.com/
[Tue Apr 19 12:34:58.975437 2016] [:error] [pid 29988] [client 82.222.218.244:59462]     django.setup(), referer: https://www.facebook.com/
[Tue Apr 19 12:34:58.975448 2016] [:error] [pid 29988] [client 82.222.218.244:59462]   File "/usr/local/lib/python2.7/dist-packages/django/__init__.py", line 18, in setup, referer: https://www.facebook.com/
[Tue Apr 19 12:34:58.975464 2016] [:error] [pid 29988] [client 82.222.218.244:59462]     apps.populate(settings.INSTALLED_APPS), referer: https://www.facebook.com/
[Tue Apr 19 12:34:58.975474 2016] [:error] [pid 29988] [client 82.222.218.244:59462]   File "/usr/local/lib/python2.7/dist-packages/django/apps/registry.py", line 78, in populate, referer: https://www.facebook.com/
[Tue Apr 19 12:34:58.975490 2016] [:error] [pid 29988] [client 82.222.218.244:59462]     raise RuntimeError("populate() isn't reentrant"), referer: https://www.facebook.com/
[Tue Apr 19 12:34:58.975509 2016] [:error] [pid 29988] [client 82.222.218.244:59462] RuntimeError: populate() isn't reentrant, referer: https://www.facebook.com/
